<?xml version="1.0" encoding="UTF-8"?>
<testng-results skipped="1" failed="0" ignored="0" total="1" passed="0">
  <reporter-output>
  </reporter-output>
  <suite name="Default suite" duration-ms="2254" started-at="2018-10-23T15:38:13Z" finished-at="2018-10-23T15:38:15Z">
    <groups>
    </groups>
    <test name="Default test" duration-ms="2254" started-at="2018-10-23T15:38:13Z" finished-at="2018-10-23T15:38:15Z">
      <class name="com.revature.tests.PrivilegeDao_Test">
        <test-method status="PASS" signature="beforeTest()[pri:0, instance:com.revature.tests.PrivilegeDao_Test@1060b431]" name="beforeTest" is-config="true" duration-ms="8" started-at="2018-10-23T15:38:13Z" finished-at="2018-10-23T15:38:13Z">
          <reporter-output>
          </reporter-output>
        </test-method> <!-- beforeTest -->
        <test-method status="FAIL" signature="beforeClass()[pri:0, instance:com.revature.tests.PrivilegeDao_Test@1060b431]" name="beforeClass" is-config="true" duration-ms="2221" started-at="2018-10-23T15:38:13Z" finished-at="2018-10-23T15:38:15Z">
          <exception class="java.lang.ExceptionInInitializerError">
            <full-stacktrace>
              <![CDATA[java.lang.ExceptionInInitializerError
at com.revature.daos.PrivilegeDaoImpl.insertPrivilege(PrivilegeDaoImpl.java:19)
at com.revature.tests.PrivilegeDao_Test.beforeClass(PrivilegeDao_Test.java:21)
at sun.reflect.NativeMethodAccessorImpl.invoke0(Native Method)
at sun.reflect.NativeMethodAccessorImpl.invoke(Unknown Source)
at sun.reflect.DelegatingMethodAccessorImpl.invoke(Unknown Source)
at java.lang.reflect.Method.invoke(Unknown Source)
at org.testng.internal.MethodInvocationHelper.invokeMethod(MethodInvocationHelper.java:124)
at org.testng.internal.MethodInvocationHelper.invokeMethodConsideringTimeout(MethodInvocationHelper.java:59)
at org.testng.internal.Invoker.invokeConfigurationMethod(Invoker.java:458)
at org.testng.internal.Invoker.invokeConfigurations(Invoker.java:222)
at org.testng.internal.Invoker.invokeConfigurations(Invoker.java:142)
at org.testng.internal.TestMethodWorker.invokeBeforeClassMethods(TestMethodWorker.java:168)
at org.testng.internal.TestMethodWorker.run(TestMethodWorker.java:105)
at org.testng.TestRunner.privateRun(TestRunner.java:648)
at org.testng.TestRunner.run(TestRunner.java:505)
at org.testng.SuiteRunner.runTest(SuiteRunner.java:455)
at org.testng.SuiteRunner.runSequentially(SuiteRunner.java:450)
at org.testng.SuiteRunner.privateRun(SuiteRunner.java:415)
at org.testng.SuiteRunner.run(SuiteRunner.java:364)
at org.testng.SuiteRunnerWorker.runSuite(SuiteRunnerWorker.java:52)
at org.testng.SuiteRunnerWorker.run(SuiteRunnerWorker.java:84)
at org.testng.TestNG.runSuitesSequentially(TestNG.java:1208)
at org.testng.TestNG.runSuitesLocally(TestNG.java:1137)
at org.testng.TestNG.runSuites(TestNG.java:1049)
at org.testng.TestNG.run(TestNG.java:1017)
at org.testng.remote.AbstractRemoteTestNG.run(AbstractRemoteTestNG.java:114)
at org.testng.remote.RemoteTestNG.initAndRun(RemoteTestNG.java:251)
at org.testng.remote.RemoteTestNG.main(RemoteTestNG.java:77)
Caused by: org.hibernate.AnnotationException: @OneToOne or @ManyToOne on com.revature.beans.Tom.privId references an unknown entity: java.lang.Integer
at org.hibernate.cfg.ToOneFkSecondPass.doSecondPass(ToOneFkSecondPass.java:109)
at org.hibernate.cfg.Configuration.processEndOfQueue(Configuration.java:1598)
at org.hibernate.cfg.Configuration.processFkSecondPassInOrder(Configuration.java:1521)
at org.hibernate.cfg.Configuration.secondPassCompile(Configuration.java:1422)
at org.hibernate.cfg.Configuration.buildSessionFactory(Configuration.java:1846)
at org.hibernate.cfg.Configuration.buildSessionFactory(Configuration.java:1930)
at com.revature.util.HibernateUtil.<clinit>(HibernateUtil.java:12)
... 28 more
]]>
            </full-stacktrace>
          </exception> <!-- java.lang.ExceptionInInitializerError -->
          <reporter-output>
          </reporter-output>
        </test-method> <!-- beforeClass -->
        <test-method status="SKIP" signature="f()[pri:0, instance:com.revature.tests.PrivilegeDao_Test@1060b431]" name="f" duration-ms="0" started-at="2018-10-23T15:38:15Z" finished-at="2018-10-23T15:38:15Z">
          <exception class="java.lang.ExceptionInInitializerError">
            <full-stacktrace>
              <![CDATA[java.lang.ExceptionInInitializerError
at com.revature.daos.PrivilegeDaoImpl.insertPrivilege(PrivilegeDaoImpl.java:19)
at com.revature.tests.PrivilegeDao_Test.beforeClass(PrivilegeDao_Test.java:21)
at sun.reflect.NativeMethodAccessorImpl.invoke0(Native Method)
at sun.reflect.NativeMethodAccessorImpl.invoke(Unknown Source)
at sun.reflect.DelegatingMethodAccessorImpl.invoke(Unknown Source)
at java.lang.reflect.Method.invoke(Unknown Source)
at org.testng.internal.MethodInvocationHelper.invokeMethod(MethodInvocationHelper.java:124)
at org.testng.internal.MethodInvocationHelper.invokeMethodConsideringTimeout(MethodInvocationHelper.java:59)
at org.testng.internal.Invoker.invokeConfigurationMethod(Invoker.java:458)
at org.testng.internal.Invoker.invokeConfigurations(Invoker.java:222)
at org.testng.internal.Invoker.invokeConfigurations(Invoker.java:142)
at org.testng.internal.TestMethodWorker.invokeBeforeClassMethods(TestMethodWorker.java:168)
at org.testng.internal.TestMethodWorker.run(TestMethodWorker.java:105)
at org.testng.TestRunner.privateRun(TestRunner.java:648)
at org.testng.TestRunner.run(TestRunner.java:505)
at org.testng.SuiteRunner.runTest(SuiteRunner.java:455)
at org.testng.SuiteRunner.runSequentially(SuiteRunner.java:450)
at org.testng.SuiteRunner.privateRun(SuiteRunner.java:415)
at org.testng.SuiteRunner.run(SuiteRunner.java:364)
at org.testng.SuiteRunnerWorker.runSuite(SuiteRunnerWorker.java:52)
at org.testng.SuiteRunnerWorker.run(SuiteRunnerWorker.java:84)
at org.testng.TestNG.runSuitesSequentially(TestNG.java:1208)
at org.testng.TestNG.runSuitesLocally(TestNG.java:1137)
at org.testng.TestNG.runSuites(TestNG.java:1049)
at org.testng.TestNG.run(TestNG.java:1017)
at org.testng.remote.AbstractRemoteTestNG.run(AbstractRemoteTestNG.java:114)
at org.testng.remote.RemoteTestNG.initAndRun(RemoteTestNG.java:251)
at org.testng.remote.RemoteTestNG.main(RemoteTestNG.java:77)
Caused by: org.hibernate.AnnotationException: @OneToOne or @ManyToOne on com.revature.beans.Tom.privId references an unknown entity: java.lang.Integer
at org.hibernate.cfg.ToOneFkSecondPass.doSecondPass(ToOneFkSecondPass.java:109)
at org.hibernate.cfg.Configuration.processEndOfQueue(Configuration.java:1598)
at org.hibernate.cfg.Configuration.processFkSecondPassInOrder(Configuration.java:1521)
at org.hibernate.cfg.Configuration.secondPassCompile(Configuration.java:1422)
at org.hibernate.cfg.Configuration.buildSessionFactory(Configuration.java:1846)
at org.hibernate.cfg.Configuration.buildSessionFactory(Configuration.java:1930)
at com.revature.util.HibernateUtil.<clinit>(HibernateUtil.java:12)
... 28 more
]]>
            </full-stacktrace>
          </exception> <!-- java.lang.ExceptionInInitializerError -->
          <reporter-output>
          </reporter-output>
        </test-method> <!-- f -->
        <test-method status="SKIP" signature="afterClass()[pri:0, instance:com.revature.tests.PrivilegeDao_Test@1060b431]" name="afterClass" is-config="true" duration-ms="0" started-at="2018-10-23T15:38:15Z" finished-at="2018-10-23T15:38:15Z">
          <reporter-output>
          </reporter-output>
        </test-method> <!-- afterClass -->
        <test-method status="SKIP" signature="afterTest()[pri:0, instance:com.revature.tests.PrivilegeDao_Test@1060b431]" name="afterTest" is-config="true" duration-ms="0" started-at="2018-10-23T15:38:15Z" finished-at="2018-10-23T15:38:15Z">
          <reporter-output>
          </reporter-output>
        </test-method> <!-- afterTest -->
      </class> <!-- com.revature.tests.PrivilegeDao_Test -->
    </test> <!-- Default test -->
  </suite> <!-- Default suite -->
</testng-results>
