<?xml version="1.0" encoding="UTF-8"?>
<!-- Generated by org.testng.reporters.JUnitXMLReporter -->
<testsuite hostname="DESKTOP-TNM7JT2" ignored="0" name="Default test" tests="1" failures="0" timestamp="23 Oct 2018 15:38:15 GMT" time="2.254" errors="0">
  <testcase name="@BeforeClass beforeClass" time="2.221" classname="com.revature.tests.PrivilegeDao_Test">
    <failure type="java.lang.ExceptionInInitializerError">
      <![CDATA[java.lang.ExceptionInInitializerError
at com.revature.daos.PrivilegeDaoImpl.insertPrivilege(PrivilegeDaoImpl.java:19)
at com.revature.tests.PrivilegeDao_Test.beforeClass(PrivilegeDao_Test.java:21)
at sun.reflect.NativeMethodAccessorImpl.invoke0(Native Method)
at sun.reflect.NativeMethodAccessorImpl.invoke(Unknown Source)
at sun.reflect.DelegatingMethodAccessorImpl.invoke(Unknown Source)
at java.lang.reflect.Method.invoke(Unknown Source)
at org.testng.internal.MethodInvocationHelper.invokeMethod(MethodInvocationHelper.java:124)
at org.testng.internal.MethodInvocationHelper.invokeMethodConsideringTimeout(MethodInvocationHelper.java:59)
at org.testng.internal.Invoker.invokeConfigurationMethod(Invoker.java:458)
at org.testng.internal.Invoker.invokeConfigurations(Invoker.java:222)
at org.testng.internal.Invoker.invokeConfigurations(Invoker.java:142)
at org.testng.internal.TestMethodWorker.invokeBeforeClassMethods(TestMethodWorker.java:168)
at org.testng.internal.TestMethodWorker.run(TestMethodWorker.java:105)
at org.testng.TestRunner.privateRun(TestRunner.java:648)
at org.testng.TestRunner.run(TestRunner.java:505)
at org.testng.SuiteRunner.runTest(SuiteRunner.java:455)
at org.testng.SuiteRunner.runSequentially(SuiteRunner.java:450)
at org.testng.SuiteRunner.privateRun(SuiteRunner.java:415)
at org.testng.SuiteRunner.run(SuiteRunner.java:364)
at org.testng.SuiteRunnerWorker.runSuite(SuiteRunnerWorker.java:52)
at org.testng.SuiteRunnerWorker.run(SuiteRunnerWorker.java:84)
at org.testng.TestNG.runSuitesSequentially(TestNG.java:1208)
at org.testng.TestNG.runSuitesLocally(TestNG.java:1137)
at org.testng.TestNG.runSuites(TestNG.java:1049)
at org.testng.TestNG.run(TestNG.java:1017)
at org.testng.remote.AbstractRemoteTestNG.run(AbstractRemoteTestNG.java:114)
at org.testng.remote.RemoteTestNG.initAndRun(RemoteTestNG.java:251)
at org.testng.remote.RemoteTestNG.main(RemoteTestNG.java:77)
Caused by: org.hibernate.AnnotationException: @OneToOne or @ManyToOne on com.revature.beans.Tom.privId references an unknown entity: java.lang.Integer
at org.hibernate.cfg.ToOneFkSecondPass.doSecondPass(ToOneFkSecondPass.java:109)
at org.hibernate.cfg.Configuration.processEndOfQueue(Configuration.java:1598)
at org.hibernate.cfg.Configuration.processFkSecondPassInOrder(Configuration.java:1521)
at org.hibernate.cfg.Configuration.secondPassCompile(Configuration.java:1422)
at org.hibernate.cfg.Configuration.buildSessionFactory(Configuration.java:1846)
at org.hibernate.cfg.Configuration.buildSessionFactory(Configuration.java:1930)
at com.revature.util.HibernateUtil.<clinit>(HibernateUtil.java:12)
... 28 more
]]>
    </failure>
  </testcase> <!-- @BeforeClass beforeClass -->
  <testcase name="@AfterClass afterClass" time="0.0" classname="com.revature.tests.PrivilegeDao_Test">
    <skipped/>
  </testcase> <!-- @AfterClass afterClass -->
  <testcase name="@AfterTest afterTest" time="0.0" classname="com.revature.tests.PrivilegeDao_Test">
    <skipped/>
  </testcase> <!-- @AfterTest afterTest -->
  <testcase name="f" time="0.0" classname="com.revature.tests.PrivilegeDao_Test">
    <skipped/>
  </testcase> <!-- f -->
</testsuite> <!-- Default test -->
